I'm sorry, but an uncaught exception occurred.

While running game code:
ScriptError: Name u'fat2' is defined twice, at game/fat1.rpy:52 and game/fat2.rpy:1.

-- Full Traceback ------------------------------------------------------------

Full traceback:
  File "/home/hedley/Documents/renpy/renpy/bootstrap.py", line 277, in bootstrap
    renpy.main.main()
  File "/home/hedley/Documents/renpy/renpy/main.py", line 354, in main
    renpy.game.script.load_script() # sets renpy.game.script.
  File "/home/hedley/Documents/renpy/renpy/script.py", line 259, in load_script
    self.load_appropriate_file(".rpyc", ".rpy", dir, fn, initcode)
  File "/home/hedley/Documents/renpy/renpy/script.py", line 738, in load_appropriate_file
    self.finish_load(stmts, initcode, filename=fn + source)
  File "/home/hedley/Documents/renpy/renpy/script.py", line 414, in finish_load
    bad_node.filename, bad_node.linenumber))
ScriptError: Name u'fat2' is defined twice, at game/fat1.rpy:52 and game/fat2.rpy:1.

Linux-4.4.0-22-generic-x86_64-with-debian-stretch-sid
Ren'Py 6.99.10.1227
 
